<mujoco>
  <compiler angle="radian" coordinate="local" />
  <option timestep="0.002" gravity="0 0 -9.81"/>


  <worldbody>
    <body name="base" pos="0 0 0">
      <geom type="sphere" size="0.05" rgba="0.7 0.2 0.2 1"/>

      <body name="link1" pos="0 0 0">
        <joint name="joint1" type="hinge" axis="0 0 1" range="-180 180"/>
        <geom type="capsule" fromto="0 0 0 0.3 0 0" size="0.03" rgba="0.2 0.2 0.7 1"/>

        <body name="link2" pos="0.3 0 0">
          <joint name="joint2" type="hinge" axis="0 0 1" range="-180 180"/>
          <geom type="capsule" fromto="0 0 0 0.3 0 0" size="0.03" rgba="0.2 0.7 0.2 1"/>
        </body>
      </body>
    </body>
  </worldbody>

  <actuator>
    <position joint="joint1" ctrlrange="0 6.28" kp="5"/>
    <position joint="joint2" ctrlrange="0 6.28" kp="5"/>
  </actuator>    
</mujoco>
